Workbook

Sheet M포인트몰양식
A1: No | B1: MALL | C1: 카테고리명 | D1: 처리상황 | E1: 주문일자 | F1: 주문번호 | G1: 상품코드 | H1: 주문상품일련번호 | I1: 상품명 | J1: 상품옵션 | K1: 업체명 | L1: 주문수량 | M1: 공급가 | N1: 판매가 | O1: 주문자아이디 | P1: 주문자명 | Q1: 주문자연락처 | R1: 수령인명 | S1: 우편번호 | T1: 주소 | U1: 상세주소 | V1: 수령인전화번호 | W1: 수령인핸드폰번호 | X1: 배송메세지 | Y1: 업체상품코드 | Z1: 결제구분 | AA1: 배송유형 | AB1: 희망일자 | AC1: 아이디
I2: [리큐엠] 고속충전 20,000mAh 대용량 보조배터리 | J2: 블랙 / 라벤더
I3: [리큐엠] 맥큐 2in1 Qi2 맥세이프 고속 오브제 무선충전기 colors4 (택1) | J3: 원더랜드 (갤럭시&애플워치 공용)
I4: [리큐엠] 고속충전 20,000mAh 대용량 보조배터리 | J4: 블랙 / 선택안함
I5: [리큐엠] 15W 고속 무선충전기 | J5: 그레이
I6: [리큐엠] 해외용 45W 5포트 여행용 고속충전 멀티충전기 | J6: 02. 화이트
I7: [리큐엠] 여행용 캐리어저울 무게측정 전자저울 color2 (택1) | J7: 화이트
I8: [리큐엠] 여행용 캐리어저울 무게측정 전자저울 color2 (택1) | J8: 화이트
I9: [리큐엠] 맥큐 2in1 Qi2 맥세이프 고속 오브제 무선충전기 colors4 (택1) | J9: 모닝브리즈 (갤럭시&애플워치 공용)
I10: [리큐엠] 맥큐 2in1 Qi2 맥세이프 고속 오브제 무선충전기 colors4 (택1) | J10: 원더랜드 (갤럭시&애플워치 공용)
I11: [리큐엠] 여행용 캐리어저울 무게측정 전자저울 color2 (택1) | J11: 화이트
I12: [리큐엠] 고속충전 20,000mAh 대용량 보조배터리 | J12: NEW세이지민트 / 민트
I13: [리큐엠] 고속충전 20,000mAh 대용량 보조배터리 | J13: NEW토마토레드 / 선택안함
I14: [리큐엠] 라이트닝 C to 8핀 실리콘 케이블
I15: [리큐엠] 고속충전 20,000mAh 대용량 보조배터리 | J15: 베이지 / 선택안함
I16: [리큐엠] 고속충전 20,000mAh 대용량 보조배터리 | J16: NEW세이지민트 / 선택안함
I17: [리큐엠] 맥세이프 삼각대 셀카봉 7단 1.3m 거치대 color2 (택1) | J17: 블랙+링스티커
I18: [리큐엠] C TO C 고속충전 실리콘 케이블 | J18: 핑크
I19: [리큐엠] C TO C 고속충전 실리콘 케이블 | J19: 블루
I20: [리큐엠] 고속충전 10,000mAh 미니 보조배터리 | J20: NEW버터 / 선택안함
I21: [리큐엠] 여행용 캐리어저울 무게측정 전자저울 color2 (택1) | J21: 화이트
I22: [리큐엠] 맥세이프 실리콘 흡착 뽁뽁이 거치대 패드 colors5 (택1) | J22: 소프트오렌지
I23: [리큐엠] 고속충전 20,000mAh 대용량 보조배터리 | J23: 베이지 / 선택안함
I24: [리큐엠] 고속충전 20,000mAh 대용량 보조배터리 | J24: 베이지 / 선택안함
I25: [리큐엠] 해외용 45W 5포트 여행용 고속충전 멀티충전기 | J25: 01. 블랙
I26: [리큐엠] 여행용 캐리어저울 무게측정 전자저울 color2 (택1) | J26: 화이트
... I47: [리큐엠] 고속충전 20,000mAh 대용량 보조배터리 | J47: 블랙 / 선택안함
I48: [리큐엠] 5000mAh 듀얼 부착 맥세이프 보조배터리
I49: [리큐엠] 15W 고속 무선충전기 | J49: 화이트
I50: [리큐엠] 고속충전 20,000mAh 대용량 보조배터리 | J50: 그린 / 선택안함
I51: [리큐엠] 해외용 45W 5포트 여행용 고속충전 멀티충전기 | J51: 01. 블랙
I52: [리큐엠] 맥세이프 삼각대 셀카봉 7단 1.3m 거치대 color2 (택1) | J52: 블랙+링스티커
I53: [리큐엠] 맥세이프 3in1 휴대용 접이식 고속 무선충전기 | J53: 블랙
I54: [리큐엠] 고속충전 20,000mAh 대용량 보조배터리 | J54: NEW세이지민트 / 민트
I55: [리큐엠] 고속충전 20,000mAh 대용량 보조배터리 | J55: NEW세이지민트 / 선택안함
I56: [리큐엠] 5000mAh 듀얼 부착 맥세이프 보조배터리
I57: [리큐엠] 5000mAh 듀얼 부착 맥세이프 보조배터리
I58: [리큐엠] C TO C 고속충전 실리콘 케이블 | J58: 블루
I59: [리큐엠] 해외용 45W 5포트 여행용 고속충전 멀티충전기 | J59: 01. 블랙
I60: [리큐엠] 해외용 45W 5포트 여행용 고속충전 멀티충전기 | J60: 02. 화이트
...

Sheet 리큐엠송장양식
A1: No | B1: MALL | C1: 카테고리명 | D1: 처리상황 | E1: 주문일자 | F1: 주문번호 | G1: 상품코드 | H1: 주문상품일련번호 | I1: 상품명 | J1: 상품옵션 | K1: 업체명 | L1: 주문수량 | M1: 공급가 | N1: 판매가 | O1: 주문자아이디 | P1: 주문자명 | Q1: 주문자연락처 | R1: 수령인명 | S1: 우편번호 | T1: 주소 | U1: 상세주소 | V1: 수령인전화번호 | W1: 수령인핸드폰번호 | X1: 배송메세지 | Y1: 업체상품코드 | Z1: 결제구분 | AA1: 배송유형 | AB1: 희망일자 | AC1: 아이디
I2: =VLOOKUP(M포인트몰양식!$I2,데이터_new!$A:$D,3,FALSE) -> QP2000C | J2: {=INDEX(데이터_new!$D:$D, MATCH(1, (데이터_new!$A:$A=M포인트몰양식!I2)*(데이터_new!$B:$B=M포인트몰양식!J2), 0))} -> 블랙 / QP2000C 실리콘케이스 핸디형 라벤더
I3: =VLOOKUP(M포인트몰양식!$I3,데이터_new!$A:$D,3,FALSE) -> ACONE | J3: {=INDEX(데이터_new!$D:$D, MATCH(1, (데이터_new!$A:$A=M포인트몰양식!I3)*(데이터_new!$B:$B=M포인트몰양식!J3), 0))} -> 원더랜드
I4: =VLOOKUP(M포인트몰양식!$I4,데이터_new!$A:$D,3,FALSE) -> QP2000C | J4: {=INDEX(데이터_new!$D:$D, MATCH(1, (데이터_new!$A:$A=M포인트몰양식!I4)*(데이터_new!$B:$B=M포인트몰양식!J4), 0))} -> 블랙
I5: =VLOOKUP(M포인트몰양식!$I5,데이터_new!$A:$D,3,FALSE) -> Q1500 | J5: {=INDEX(데이터_new!$D:$D, MATCH(1, (데이터_new!$A:$A=M포인트몰양식!I5)*(데이터_new!$B:$B=M포인트몰양식!J5), 0))} -> 그레이
I6: =VLOOKUP(M포인트몰양식!$I6,데이터_new!$A:$D,3,FALSE) -> 여행용어댑터 | J6: {=INDEX(데이터_new!$D:$D, MATCH(1, (데이터_new!$A:$A=M포인트몰양식!I6)*(데이터_new!$B:$B=M포인트몰양식!J6), 0))} -> 화이트
I7: =VLOOKUP(M포인트몰양식!$I7,데이터_new!$A:$D,3,FALSE) -> 여행용 캐리어저울 | J7: {=INDEX(데이터_new!$D:$D, MATCH(1, (데이터_new!$A:$A=M포인트몰양식!I7)*(데이터_new!$B:$B=M포인트몰양식!J7), 0))} -> 화이트
I8: =VLOOKUP(M포인트몰양식!$I8,데이터_new!$A:$D,3,FALSE) -> 여행용 캐리어저울 | J8: {=INDEX(데이터_new!$D:$D, MATCH(1, (데이터_new!$A:$A=M포인트몰양식!I8)*(데이터_new!$B:$B=M포인트몰양식!J8), 0))} -> 화이트
I9: =VLOOKUP(M포인트몰양식!$I9,데이터_new!$A:$D,3,FALSE) -> ACONE | J9: {=INDEX(데이터_new!$D:$D, MATCH(1, (데이터_new!$A:$A=M포인트몰양식!I9)*(데이터_new!$B:$B=M포인트몰양식!J9), 0))} -> 모닝브리즈
I10: =VLOOKUP(M포인트몰양식!$I10,데이터_new!$A:$D,3,FALSE) -> ACONE | J10: {=INDEX(데이터_new!$D:$D, MATCH(1, (데이터_new!$A:$A=M포인트몰양식!I10)*(데이터_new!$B:$B=M포인트몰양식!J10), 0))} -> 원더랜드
I11: =VLOOKUP(M포인트몰양식!$I11,데이터_new!$A:$D,3,FALSE) -> 여행용 캐리어저울 | J11: {=INDEX(데이터_new!$D:$D, MATCH(1, (데이터_new!$A:$A=M포인트몰양식!I11)*(데이터_new!$B:$B=M포인트몰양식!J11), 0))} -> 화이트
I12: =VLOOKUP(M포인트몰양식!$I12,데이터_new!$A:$D,3,FALSE) -> QP2000C | J12: {=INDEX(데이터_new!$D:$D, MATCH(1, (데이터_new!$A:$A=M포인트몰양식!I12)*(데이터_new!$B:$B=M포인트몰양식!J12), 0))} -> 세이지민트 / QP2000C 실리콘케이스 핸디형 민트
I13: =VLOOKUP(M포인트몰양식!$I13,데이터_new!$A:$D,3,FALSE) -> QP2000C | J13: {=INDEX(데이터_new!$D:$D, MATCH(1, (데이터_new!$A:$A=M포인트몰양식!I13)*(데이터_new!$B:$B=M포인트몰양식!J13), 0))} -> 토마토레드
... I500: =VLOOKUP(M포인트몰양식!$I500,데이터_new!$A:$D,3,FALSE) -> #N/A | J500: {=INDEX(데이터_new!$D:$D, MATCH(1, (데이터_new!$A:$A=M포인트몰양식!I500)*(데이터_new!$B:$B=M포인트몰양식!J500), 0))} -> 0

Sheet 데이터_new
A1: [리큐엠] | B1: 상품옵션 | C1: 상품명 | D1: 색상,옵션
A2: [리큐엠] 고속충전 20,000mAh 대용량 보조배터리 | B2: 블랙 / 선택안함 | C2: QP2000C | D2: 블랙
A3: [리큐엠] 고속충전 20,000mAh 대용량 보조배터리 | B3: 블랙 / 민트 | C3: QP2000C | D3: 블랙 / QP2000C 실리콘케이스 핸디형 민트
A4: [리큐엠] 고속충전 20,000mAh 대용량 보조배터리 | B4: 블랙 / 핑크 | C4: QP2000C | D4: 블랙 / QP2000C 실리콘케이스 핸디형 핑크
A5: [리큐엠] 고속충전 20,000mAh 대용량 보조배터리 | B5: 블랙 / 샌드 | C5: QP2000C | D5: 블랙 / QP2000C 실리콘케이스 핸디형 샌드
A6: [리큐엠] 고속충전 20,000mAh 대용량 보조배터리 | B6: 블랙 / 라벤더 | C6: QP2000C | D6: 블랙 / QP2000C 실리콘케이스 핸디형 라벤더
A8: [리큐엠] 고속충전 20,000mAh 대용량 보조배터리 | B8: 화이트 / 선택안함 | C8: QP2000C | D8: 화이트
A9: [리큐엠] 고속충전 20,000mAh 대용량 보조배터리 | B9: 화이트 / 민트 | C9: QP2000C | D9: 화이트 / QP2000C 실리콘케이스 핸디형 민트
A10: [리큐엠] 고속충전 20,000mAh 대용량 보조배터리 | B10: 화이트 / 핑크 | C10: QP2000C | D10: 화이트 / QP2000C 실리콘케이스 핸디형 핑크
A11: [리큐엠] 고속충전 20,000mAh 대용량 보조배터리 | B11: 화이트 / 샌드 | C11: QP2000C | D11: 화이트 / QP2000C 실리콘케이스 핸디형 샌드
A12: [리큐엠] 고속충전 20,000mAh 대용량 보조배터리 | B12: 화이트 / 라벤더 | C12: QP2000C | D12: 화이트 / QP2000C 실리콘케이스 핸디형 라벤더
A14: [리큐엠] 고속충전 20,000mAh 대용량 보조배터리 | B14: 베이지 / 선택안함 | C14: QP2000C | D14: 베이지
... A182: [리큐엠] 여행용 캐리어저울 무게측정 전자저울 color2 (택1) | B182: 화이트 | C182: 여행용 캐리어저울 | D182: 화이트
A184: [리큐엠] 라이트닝 C to 8핀 실리콘 케이블 | C184: 실리케이블 | D184: 8핀
A186: [리큐엠] 올인원 15W 고속 무선충전 선물세트 | B186: 02. 핑크 | C186: SOMEONE | D186: 핑크
A187: [리큐엠] 올인원 15W 고속 무선충전 선물세트 | B187: 01. 블루 | C187: SOMEONE | D187: 블루
A189: [리큐엠] 휴대용 9000mAh 손난로 보조배터리 | B189: 올리브그린 | C189: 핸디워머 | D189: 그린
A190: [리큐엠] 휴대용 9000mAh 손난로 보조배터리 | B190: 파스텔핑크 | C190: 핸디워머 | D190: 핑크
A192: [리큐엠] 고속충전 20,000mAh 대용량 보조배터리 | B192: 그린 / 선택안함 | C192: QP2000C | D192: 그린
A193: [리큐엠] 고속충전 20,000mAh 대용량 보조배터리 | B193: 그린 / 민트 | C193: QP2000C | D193: 그린 / QP2000C 실리콘케이스 핸디형 민트
A194: [리큐엠] 고속충전 20,000mAh 대용량 보조배터리 | B194: 그린 / 핑크 | C194: QP2000C | D194: 그린 / QP2000C 실리콘케이스 핸디형 핑크
A195: [리큐엠] 고속충전 20,000mAh 대용량 보조배터리 | B195: 그린 / 샌드 | C195: QP2000C | D195: 그린 / QP2000C 실리콘케이스 핸디형 샌드
A196: [리큐엠] 고속충전 20,000mAh 대용량 보조배터리 | B196: 그린 / 라벤더 | C196: QP2000C | D196: 그린 / QP2000C 실리콘케이스 핸디형 라벤더
A199: [리큐엠] 5000mAh 듀얼 부착 맥세이프 보조배터리 | C199: QMP5 | D199: 화이트
A201: [리큐엠] 맥세이프 3in1 고속 무선충전기(애플워치 보조배터리 포함) | B201: 솔리드 그레이 | C201: QM4100 | D201: 솔리드 그레이
A202: [리큐엠] 맥세이프 3in1 고속 무선충전기(애플워치 보조배터리 포함)
A204: [리큐엠] 5in1 무드등 접이식 시계 고속무선충전기 (택1) | B204: 01. 애플워치용 | C204: L5100 | D204: 애플 전용
A205: [리큐엠] 5in1 무드등 접이식 시계 고속무선충전기 (택1) | B205: 02. 갤럭시워치용 | C205: L5100 | D205: 갤럭시 전용
A207: [리큐엠] 맥세이프 실리콘 흡착 뽁뽁이 거치대 패드 colors5 (택1) | B207: 소프트 크림 | C207: 버블패드 | D207: 소프트 크림
A208: [리큐엠] 맥세이프 실리콘 흡착 뽁뽁이 거치대 패드 colors5 (택1) | B208: 소프트 블루 | C208: 버블패드 | D208: 소프트 블루
A209: [리큐엠] 맥세이프 실리콘 흡착 뽁뽁이 거치대 패드 colors5 (택1) | B209: 소프트 블랙 | C209: 버블패드 | D209: 소프트 블랙
A210: [리큐엠] 맥세이프 실리콘 흡착 뽁뽁이 거치대 패드 colors5 (택1) | B210: 소프트 라벤더 | C210: 버블패드 | D210: 소프트 라벤더
A211: [리큐엠] 맥세이프 실리콘 흡착 뽁뽁이 거치대 패드 colors5 (택1) | B211: 소프트 민트 | C211: 버블패드 | D211: 소프트 민트
A213: [리큐엠] 고속충전 20,000mAh 대용량 보조배터리 | B213: NEW토마토레드 / 선택안함 | C213: QP2000C | D213: 토마토레드
A214: [리큐엠] 고속충전 20,000mAh 대용량 보조배터리 | B214: NEW토마토레드 / 민트 | C214: QP2000C | D214: 토마토레드 / QP2000C 실리콘케이스 핸디형 민트
A215: [리큐엠] 고속충전 20,000mAh 대용량 보조배터리 | B215: NEW토마토레드 / 핑크 | C215: QP2000C | D215: 토마토레드 / QP2000C 실리콘케이스 핸디형 핑크
A216: [리큐엠] 고속충전 20,000mAh 대용량 보조배터리 | B216: NEW토마토레드 / 샌드 | C216: QP2000C | D216: 토마토레드 / QP2000C 실리콘케이스 핸디형 샌드
A217: [리큐엠] 고속충전 20,000mAh 대용량 보조배터리 | B217: NEW토마토레드 / 라벤더 | C217: QP2000C | D217: 토마토레드 / QP2000C 실리콘케이스 핸디형 라벤더
... A244: [리큐엠] 맥세이프 3in1 휴대용 접이식 고속 무선충전기 | B244: 화이트 | C244: T3100 | D244: 화이트
